[2023-12-02T00:43:17.795+0000] {taskinstance.py:1159} INFO - Dependencies all met for dep_context=non-requeueable deps ti=<TaskInstance: pubsub_pandas_dag.retrieve_messages manual__2023-12-02T00:43:17.095364+00:00 [queued]>
[2023-12-02T00:43:17.803+0000] {taskinstance.py:1159} INFO - Dependencies all met for dep_context=requeueable deps ti=<TaskInstance: pubsub_pandas_dag.retrieve_messages manual__2023-12-02T00:43:17.095364+00:00 [queued]>
[2023-12-02T00:43:17.803+0000] {taskinstance.py:1361} INFO - Starting attempt 1 of 2
[2023-12-02T00:43:17.814+0000] {taskinstance.py:1382} INFO - Executing <Task(PythonOperator): retrieve_messages> on 2023-12-02 00:43:17.095364+00:00
[2023-12-02T00:43:17.820+0000] {standard_task_runner.py:57} INFO - Started process 351 to run task
[2023-12-02T00:43:17.821+0000] {standard_task_runner.py:84} INFO - Running: ['***', 'tasks', 'run', 'pubsub_pandas_dag', 'retrieve_messages', 'manual__2023-12-02T00:43:17.095364+00:00', '--job-id', '7', '--raw', '--subdir', 'DAGS_FOLDER/process_pubsub_message.py', '--cfg-path', '/tmp/tmp89z0te4m']
[2023-12-02T00:43:17.824+0000] {standard_task_runner.py:85} INFO - Job 7: Subtask retrieve_messages
[2023-12-02T00:43:17.836+0000] {logging_mixin.py:154} WARNING - /home/***/.local/lib/python3.8/site-packages/***/settings.py:195 DeprecationWarning: The sql_alchemy_conn option in [core] has been moved to the sql_alchemy_conn option in [database] - the old setting has been used, but please update your config.
[2023-12-02T00:43:17.867+0000] {task_command.py:416} INFO - Running <TaskInstance: pubsub_pandas_dag.retrieve_messages manual__2023-12-02T00:43:17.095364+00:00 [running]> on host 2fdb813c544a
[2023-12-02T00:43:17.934+0000] {taskinstance.py:1662} INFO - Exporting env vars: AIRFLOW_CTX_DAG_OWNER='***' AIRFLOW_CTX_DAG_ID='pubsub_pandas_dag' AIRFLOW_CTX_TASK_ID='retrieve_messages' AIRFLOW_CTX_EXECUTION_DATE='2023-12-02T00:43:17.095364+00:00' AIRFLOW_CTX_TRY_NUMBER='1' AIRFLOW_CTX_DAG_RUN_ID='manual__2023-12-02T00:43:17.095364+00:00'
[2023-12-02T00:43:17.936+0000] {taskinstance.py:1937} ERROR - Task failed with exception
Traceback (most recent call last):
  File "/home/airflow/.local/lib/python3.8/site-packages/airflow/operators/python.py", line 192, in execute
    return_value = self.execute_callable()
  File "/home/airflow/.local/lib/python3.8/site-packages/airflow/operators/python.py", line 209, in execute_callable
    return self.python_callable(*self.op_args, **self.op_kwargs)
  File "/opt/airflow/dags/process_pubsub_message.py", line 15, in retrieve_pubsub_messages_to_xcom
    credentials = service_account.Credentials.from_service_account_file(
  File "/home/airflow/.local/lib/python3.8/site-packages/google/oauth2/service_account.py", line 260, in from_service_account_file
    info, signer = _service_account_info.from_filename(
  File "/home/airflow/.local/lib/python3.8/site-packages/google/auth/_service_account_info.py", line 78, in from_filename
    with io.open(filename, "r", encoding="utf-8") as json_file:
FileNotFoundError: [Errno 2] No such file or directory: '/opt/airflow/config/credentials.json'
[2023-12-02T00:43:17.947+0000] {taskinstance.py:1400} INFO - Marking task as UP_FOR_RETRY. dag_id=pubsub_pandas_dag, task_id=retrieve_messages, execution_date=20231202T004317, start_date=20231202T004317, end_date=20231202T004317
[2023-12-02T00:43:17.956+0000] {standard_task_runner.py:104} ERROR - Failed to execute job 7 for task retrieve_messages ([Errno 2] No such file or directory: '/opt/airflow/config/credentials.json'; 351)
[2023-12-02T00:43:17.994+0000] {local_task_job_runner.py:228} INFO - Task exited with return code 1
[2023-12-02T00:43:18.015+0000] {taskinstance.py:2778} INFO - 0 downstream tasks scheduled from follow-on schedule check
