[2023-12-02T01:05:08.052+0000] {taskinstance.py:1159} INFO - Dependencies all met for dep_context=non-requeueable deps ti=<TaskInstance: pubsub_pandas_dag.retrieve_messages scheduled__2023-12-01T01:00:00.696767+00:00 [queued]>
[2023-12-02T01:05:08.058+0000] {taskinstance.py:1159} INFO - Dependencies all met for dep_context=requeueable deps ti=<TaskInstance: pubsub_pandas_dag.retrieve_messages scheduled__2023-12-01T01:00:00.696767+00:00 [queued]>
[2023-12-02T01:05:08.059+0000] {taskinstance.py:1361} INFO - Starting attempt 2 of 2
[2023-12-02T01:05:08.068+0000] {taskinstance.py:1382} INFO - Executing <Task(PythonOperator): retrieve_messages> on 2023-12-01 01:00:00.696767+00:00
[2023-12-02T01:05:08.072+0000] {standard_task_runner.py:57} INFO - Started process 594 to run task
[2023-12-02T01:05:08.073+0000] {standard_task_runner.py:84} INFO - Running: ['***', 'tasks', 'run', 'pubsub_pandas_dag', 'retrieve_messages', 'scheduled__2023-12-01T01:00:00.696767+00:00', '--job-id', '8', '--raw', '--subdir', 'DAGS_FOLDER/process_pubsub_message.py', '--cfg-path', '/tmp/tmplt0ip7v7']
[2023-12-02T01:05:08.075+0000] {standard_task_runner.py:85} INFO - Job 8: Subtask retrieve_messages
[2023-12-02T01:05:08.084+0000] {logging_mixin.py:154} WARNING - /home/***/.local/lib/python3.8/site-packages/***/settings.py:195 DeprecationWarning: The sql_alchemy_conn option in [core] has been moved to the sql_alchemy_conn option in [database] - the old setting has been used, but please update your config.
[2023-12-02T01:05:08.109+0000] {task_command.py:416} INFO - Running <TaskInstance: pubsub_pandas_dag.retrieve_messages scheduled__2023-12-01T01:00:00.696767+00:00 [running]> on host dc391b67cb0e
[2023-12-02T01:05:08.160+0000] {taskinstance.py:1662} INFO - Exporting env vars: AIRFLOW_CTX_DAG_OWNER='***' AIRFLOW_CTX_DAG_ID='pubsub_pandas_dag' AIRFLOW_CTX_TASK_ID='retrieve_messages' AIRFLOW_CTX_EXECUTION_DATE='2023-12-01T01:00:00.696767+00:00' AIRFLOW_CTX_TRY_NUMBER='2' AIRFLOW_CTX_DAG_RUN_ID='scheduled__2023-12-01T01:00:00.696767+00:00'
[2023-12-02T01:05:08.736+0000] {taskinstance.py:1937} ERROR - Task failed with exception
Traceback (most recent call last):
  File "/home/airflow/.local/lib/python3.8/site-packages/google/api_core/grpc_helpers.py", line 75, in error_remapped_callable
    return callable_(*args, **kwargs)
  File "/home/airflow/.local/lib/python3.8/site-packages/grpc/_channel.py", line 1161, in __call__
    return _end_unary_response_blocking(state, call, False, None)
  File "/home/airflow/.local/lib/python3.8/site-packages/grpc/_channel.py", line 1004, in _end_unary_response_blocking
    raise _InactiveRpcError(state)  # pytype: disable=not-instantiable
grpc._channel._InactiveRpcError: <_InactiveRpcError of RPC that terminated with:
	status = StatusCode.NOT_FOUND
	details = "Resource not found (resource=your-subscription-id)."
	debug_error_string = "UNKNOWN:Error received from peer ipv4:142.250.200.42:443 {created_time:"2023-12-02T01:05:08.735669834+00:00", grpc_status:5, grpc_message:"Resource not found (resource=your-subscription-id)."}"
>

The above exception was the direct cause of the following exception:

Traceback (most recent call last):
  File "/home/airflow/.local/lib/python3.8/site-packages/airflow/operators/python.py", line 192, in execute
    return_value = self.execute_callable()
  File "/home/airflow/.local/lib/python3.8/site-packages/airflow/operators/python.py", line 209, in execute_callable
    return self.python_callable(*self.op_args, **self.op_kwargs)
  File "/opt/airflow/dags/process_pubsub_message.py", line 23, in retrieve_pubsub_messages_to_xcom
    response = subscriber.pull(
  File "/home/airflow/.local/lib/python3.8/site-packages/google/pubsub_v1/services/subscriber/client.py", line 1495, in pull
    response = rpc(
  File "/home/airflow/.local/lib/python3.8/site-packages/google/api_core/gapic_v1/method.py", line 131, in __call__
    return wrapped_func(*args, **kwargs)
  File "/home/airflow/.local/lib/python3.8/site-packages/google/api_core/retry.py", line 366, in retry_wrapped_func
    return retry_target(
  File "/home/airflow/.local/lib/python3.8/site-packages/google/api_core/retry.py", line 204, in retry_target
    return target()
  File "/home/airflow/.local/lib/python3.8/site-packages/google/api_core/timeout.py", line 120, in func_with_timeout
    return func(*args, **kwargs)
  File "/home/airflow/.local/lib/python3.8/site-packages/google/api_core/grpc_helpers.py", line 77, in error_remapped_callable
    raise exceptions.from_grpc_error(exc) from exc
google.api_core.exceptions.NotFound: 404 Resource not found (resource=your-subscription-id).
[2023-12-02T01:05:08.747+0000] {taskinstance.py:1400} INFO - Marking task as FAILED. dag_id=pubsub_pandas_dag, task_id=retrieve_messages, execution_date=20231201T010000, start_date=20231202T010508, end_date=20231202T010508
[2023-12-02T01:05:08.756+0000] {standard_task_runner.py:104} ERROR - Failed to execute job 8 for task retrieve_messages (404 Resource not found (resource=your-subscription-id).; 594)
[2023-12-02T01:05:08.768+0000] {local_task_job_runner.py:228} INFO - Task exited with return code 1
[2023-12-02T01:05:08.782+0000] {taskinstance.py:2778} INFO - 0 downstream tasks scheduled from follow-on schedule check
