[2023-12-01T23:34:00.701+0000] {taskinstance.py:1159} INFO - Dependencies all met for dep_context=non-requeueable deps ti=<TaskInstance: pubsub_pandas_dag.retrieve_messages manual__2023-12-01T23:33:59.981111+00:00 [queued]>
[2023-12-01T23:34:00.709+0000] {taskinstance.py:1159} INFO - Dependencies all met for dep_context=requeueable deps ti=<TaskInstance: pubsub_pandas_dag.retrieve_messages manual__2023-12-01T23:33:59.981111+00:00 [queued]>
[2023-12-01T23:34:00.709+0000] {taskinstance.py:1361} INFO - Starting attempt 1 of 2
[2023-12-01T23:34:00.721+0000] {taskinstance.py:1382} INFO - Executing <Task(PythonOperator): retrieve_messages> on 2023-12-01 23:33:59.981111+00:00
[2023-12-01T23:34:00.726+0000] {standard_task_runner.py:57} INFO - Started process 1458 to run task
[2023-12-01T23:34:00.728+0000] {standard_task_runner.py:84} INFO - Running: ['***', 'tasks', 'run', 'pubsub_pandas_dag', 'retrieve_messages', 'manual__2023-12-01T23:33:59.981111+00:00', '--job-id', '22', '--raw', '--subdir', 'DAGS_FOLDER/process_pubsub_message.py', '--cfg-path', '/tmp/tmpveqcqjur']
[2023-12-01T23:34:00.730+0000] {standard_task_runner.py:85} INFO - Job 22: Subtask retrieve_messages
[2023-12-01T23:34:00.775+0000] {task_command.py:416} INFO - Running <TaskInstance: pubsub_pandas_dag.retrieve_messages manual__2023-12-01T23:33:59.981111+00:00 [running]> on host cbfe888ad84e
[2023-12-01T23:34:00.848+0000] {taskinstance.py:1662} INFO - Exporting env vars: AIRFLOW_CTX_DAG_OWNER='***' AIRFLOW_CTX_DAG_ID='pubsub_pandas_dag' AIRFLOW_CTX_TASK_ID='retrieve_messages' AIRFLOW_CTX_EXECUTION_DATE='2023-12-01T23:33:59.981111+00:00' AIRFLOW_CTX_TRY_NUMBER='1' AIRFLOW_CTX_DAG_RUN_ID='manual__2023-12-01T23:33:59.981111+00:00'
[2023-12-01T23:34:00.852+0000] {taskinstance.py:1937} ERROR - Task failed with exception
Traceback (most recent call last):
  File "/home/airflow/.local/lib/python3.8/site-packages/airflow/operators/python.py", line 192, in execute
    return_value = self.execute_callable()
  File "/home/airflow/.local/lib/python3.8/site-packages/airflow/operators/python.py", line 209, in execute_callable
    return self.python_callable(*self.op_args, **self.op_kwargs)
  File "/opt/airflow/dags/process_pubsub_message.py", line 12, in retrieve_pubsub_messages_to_xcom
    subscriber = pubsub_v1.SubscriberClient()
  File "/home/airflow/.local/lib/python3.8/site-packages/google/cloud/pubsub_v1/subscriber/client.py", line 81, in __init__
    super().__init__(**kwargs)
  File "/home/airflow/.local/lib/python3.8/site-packages/google/pubsub_v1/services/subscriber/client.py", line 496, in __init__
    self._transport = Transport(
  File "/home/airflow/.local/lib/python3.8/site-packages/google/pubsub_v1/services/subscriber/transports/grpc.py", line 155, in __init__
    super().__init__(
  File "/home/airflow/.local/lib/python3.8/site-packages/google/pubsub_v1/services/subscriber/transports/base.py", line 104, in __init__
    credentials, _ = google.auth.default(
  File "/home/airflow/.local/lib/python3.8/site-packages/google/auth/_default.py", line 657, in default
    credentials, project_id = checker()
  File "/home/airflow/.local/lib/python3.8/site-packages/google/auth/_default.py", line 650, in <lambda>
    lambda: _get_explicit_environ_credentials(quota_project_id=quota_project_id),
  File "/home/airflow/.local/lib/python3.8/site-packages/google/auth/_default.py", line 270, in _get_explicit_environ_credentials
    credentials, project_id = load_credentials_from_file(
  File "/home/airflow/.local/lib/python3.8/site-packages/google/auth/_default.py", line 114, in load_credentials_from_file
    raise exceptions.DefaultCredentialsError(
google.auth.exceptions.DefaultCredentialsError: File C:\Users\rober\Documents\DevsMentoring\_DevsMentoring_\Python\***\docker-implementation\config\credentials.json was not found.
[2023-12-01T23:34:00.879+0000] {taskinstance.py:1400} INFO - Marking task as UP_FOR_RETRY. dag_id=pubsub_pandas_dag, task_id=retrieve_messages, execution_date=20231201T233359, start_date=20231201T233400, end_date=20231201T233400
[2023-12-01T23:34:00.901+0000] {standard_task_runner.py:104} ERROR - Failed to execute job 22 for task retrieve_messages (File C:\Users\rober\Documents\DevsMentoring\_DevsMentoring_\Python\***\docker-implementation\config\credentials.json was not found.; 1458)
[2023-12-01T23:34:00.940+0000] {local_task_job_runner.py:228} INFO - Task exited with return code 1
[2023-12-01T23:34:00.963+0000] {taskinstance.py:2778} INFO - 0 downstream tasks scheduled from follow-on schedule check
