[2023-12-21T13:15:24.925+0000] {logging_mixin.py:154} INFO - Changing /opt/***/logs/dag_id=pubsub_pandas_dag/run_id=manual__2023-12-21T13:15:23.494016+00:00/task_id=retrieve_messages permission to 509
[2023-12-21T13:15:24.956+0000] {logging_mixin.py:154} INFO - Changing /opt/***/logs/dag_id=pubsub_pandas_dag/run_id=manual__2023-12-21T13:15:23.494016+00:00/task_id=retrieve_messages permission to 509
[2023-12-21T13:15:24.991+0000] {taskinstance.py:1159} INFO - Dependencies all met for dep_context=non-requeueable deps ti=<TaskInstance: pubsub_pandas_dag.retrieve_messages manual__2023-12-21T13:15:23.494016+00:00 [queued]>
[2023-12-21T13:15:24.998+0000] {taskinstance.py:1159} INFO - Dependencies all met for dep_context=requeueable deps ti=<TaskInstance: pubsub_pandas_dag.retrieve_messages manual__2023-12-21T13:15:23.494016+00:00 [queued]>
[2023-12-21T13:15:24.999+0000] {taskinstance.py:1361} INFO - Starting attempt 1 of 2
[2023-12-21T13:15:25.011+0000] {taskinstance.py:1382} INFO - Executing <Task(PythonOperator): retrieve_messages> on 2023-12-21 13:15:23.494016+00:00
[2023-12-21T13:15:25.015+0000] {standard_task_runner.py:57} INFO - Started process 4213 to run task
[2023-12-21T13:15:25.017+0000] {standard_task_runner.py:84} INFO - Running: ['***', 'tasks', 'run', 'pubsub_pandas_dag', 'retrieve_messages', 'manual__2023-12-21T13:15:23.494016+00:00', '--job-id', '7', '--raw', '--subdir', 'DAGS_FOLDER/process_pubsub_message.py', '--cfg-path', '/tmp/tmpab69xz9h']
[2023-12-21T13:15:25.021+0000] {standard_task_runner.py:85} INFO - Job 7: Subtask retrieve_messages
[2023-12-21T13:15:25.034+0000] {logging_mixin.py:154} WARNING - /home/***/.local/lib/python3.8/site-packages/***/settings.py:195 DeprecationWarning: The sql_alchemy_conn option in [core] has been moved to the sql_alchemy_conn option in [database] - the old setting has been used, but please update your config.
[2023-12-21T13:15:25.063+0000] {logging_mixin.py:154} INFO - Changing /opt/***/logs/dag_id=pubsub_pandas_dag/run_id=manual__2023-12-21T13:15:23.494016+00:00/task_id=retrieve_messages permission to 509
[2023-12-21T13:15:25.072+0000] {task_command.py:416} INFO - Running <TaskInstance: pubsub_pandas_dag.retrieve_messages manual__2023-12-21T13:15:23.494016+00:00 [running]> on host 491e3d3d49e0
[2023-12-21T13:15:25.133+0000] {taskinstance.py:1662} INFO - Exporting env vars: AIRFLOW_CTX_DAG_OWNER='***' AIRFLOW_CTX_DAG_ID='pubsub_pandas_dag' AIRFLOW_CTX_TASK_ID='retrieve_messages' AIRFLOW_CTX_EXECUTION_DATE='2023-12-21T13:15:23.494016+00:00' AIRFLOW_CTX_TRY_NUMBER='1' AIRFLOW_CTX_DAG_RUN_ID='manual__2023-12-21T13:15:23.494016+00:00'
[2023-12-21T13:15:25.869+0000] {taskinstance.py:1937} ERROR - Task failed with exception
Traceback (most recent call last):
  File "/home/airflow/.local/lib/python3.8/site-packages/google/api_core/grpc_helpers.py", line 75, in error_remapped_callable
    return callable_(*args, **kwargs)
  File "/home/airflow/.local/lib/python3.8/site-packages/grpc/_channel.py", line 1161, in __call__
    return _end_unary_response_blocking(state, call, False, None)
  File "/home/airflow/.local/lib/python3.8/site-packages/grpc/_channel.py", line 1004, in _end_unary_response_blocking
    raise _InactiveRpcError(state)  # pytype: disable=not-instantiable
grpc._channel._InactiveRpcError: <_InactiveRpcError of RPC that terminated with:
	status = StatusCode.NOT_FOUND
	details = "Resource not found (resource=your-subscription-id)."
	debug_error_string = "UNKNOWN:Error received from peer ipv4:142.250.186.202:443 {created_time:"2023-12-21T13:15:25.8638178+00:00", grpc_status:5, grpc_message:"Resource not found (resource=your-subscription-id)."}"
>

The above exception was the direct cause of the following exception:

Traceback (most recent call last):
  File "/home/airflow/.local/lib/python3.8/site-packages/airflow/operators/python.py", line 192, in execute
    return_value = self.execute_callable()
  File "/home/airflow/.local/lib/python3.8/site-packages/airflow/operators/python.py", line 209, in execute_callable
    return self.python_callable(*self.op_args, **self.op_kwargs)
  File "/opt/airflow/dags/process_pubsub_message.py", line 38, in retrieve_pubsub_messages_to_xcom
    response = subscriber.pull(
  File "/home/airflow/.local/lib/python3.8/site-packages/google/pubsub_v1/services/subscriber/client.py", line 1495, in pull
    response = rpc(
  File "/home/airflow/.local/lib/python3.8/site-packages/google/api_core/gapic_v1/method.py", line 131, in __call__
    return wrapped_func(*args, **kwargs)
  File "/home/airflow/.local/lib/python3.8/site-packages/google/api_core/retry.py", line 366, in retry_wrapped_func
    return retry_target(
  File "/home/airflow/.local/lib/python3.8/site-packages/google/api_core/retry.py", line 204, in retry_target
    return target()
  File "/home/airflow/.local/lib/python3.8/site-packages/google/api_core/timeout.py", line 120, in func_with_timeout
    return func(*args, **kwargs)
  File "/home/airflow/.local/lib/python3.8/site-packages/google/api_core/grpc_helpers.py", line 77, in error_remapped_callable
    raise exceptions.from_grpc_error(exc) from exc
google.api_core.exceptions.NotFound: 404 Resource not found (resource=your-subscription-id).
[2023-12-21T13:15:25.888+0000] {taskinstance.py:1400} INFO - Marking task as UP_FOR_RETRY. dag_id=pubsub_pandas_dag, task_id=retrieve_messages, execution_date=20231221T131523, start_date=20231221T131524, end_date=20231221T131525
[2023-12-21T13:15:25.902+0000] {standard_task_runner.py:104} ERROR - Failed to execute job 7 for task retrieve_messages (404 Resource not found (resource=your-subscription-id).; 4213)
[2023-12-21T13:15:25.916+0000] {local_task_job_runner.py:228} INFO - Task exited with return code 1
[2023-12-21T13:15:25.937+0000] {taskinstance.py:2778} INFO - 0 downstream tasks scheduled from follow-on schedule check
